using LessonA.Dayone;
using System;
using System.Collections.Generic;
using System.Linq;
using System.Text;
using System.Threading.Tasks;

namespace LessonA.DayThree
{
    internal class ExceptionalDemo
    {
        class Calculator
        {
            public int Divide(int x, int y)
            {
                return x / y;
            }
            public int Add(int x, int y)
            {
                return x + y;
            }
            public int Multiply(int x, int y)
            {
                return x * y;
            }
            public int Subtract(int x, int y)
            {
                return x - y;
            }

            //public int DivideA(int x, int y)
            //{
            //    //if (y == 0)
            //    //    throw new ZeroValueException();
            //    //if (y == 0)
            //    //    throw new ZeroValueException("ERROR!!! Value for Y is " + y);
            //    //return x / y;
            //}
        }
        public static void DemoAExceptions()
        {
            Console.WriteLine("\tEnter a no for X");
            int x = int.Parse(Console.ReadLine());
            Console.WriteLine("\tEnter a no Y");
            int y = int.Parse(Console.ReadLine());
            Calculator c1 = new Calculator();
            int z = c1.Divide(x, y);
            Console.WriteLine("Result in M3 " + z);
        }
        public static void TestDivide()
        {
            Calculator c1 = null;
            int v1 = 0;
            int v2 = 0;
            int v3 = 0;
            try
            {
                Console.WriteLine("Enter a no X");
                v1 = int.Parse(Console.ReadLine());
                Console.WriteLine("Enter another no Y");
                v2 = int.Parse(Console.ReadLine());
                c1 = new Calculator();
                v3 = c1.Divide(v1, v2);
                Console.WriteLine("Result of {0}/{1}={2}", v1, v2, v3);
            }
            catch (Exception err)
            {
                Console.WriteLine("Error1 Type " + err.GetType().FullName);
                Console.WriteLine("Error1 Message " + err.Message);
                Console.WriteLine("Error1 SOURCE " + err.Source);
                Console.WriteLine("Error1 TargetSite " + err.TargetSite.Name);
            }
        }
        public static void TestCatchFinally()
        {
            Console.WriteLine("Before Try");
            int v1 = 0;
            // return;
            try
            {
                Console.WriteLine("Inside Try");
                Console.WriteLine("Enter a no");
                v1 = int.Parse(Console.ReadLine());
               
            }
            catch (Exception err)
            {
                Console.WriteLine("Inside Catch " + err.Message);
            }
            finally
            {
                Console.WriteLine("Inside  Finally");
            }
            Console.WriteLine("After  Finally");
        }
        class ClassA
        {
            public int M1(int x, int y)
            {
                ClassB b1 = new ClassB();
                return b1.M2(x, y);
            }
        }
        class ClassB
        {
            public int M2(int x, int y)
            {
                Calculator c1 = new Calculator();
                return c1.Divide(x, y);
            }
        }
        public static void TestStackTrace()
        {
            ClassA a1 = null;
            int v1 = 0;
            int v2 = 0;
            int v3 = 0;
            try
            {
                Console.WriteLine("Enter a no X");
                v1 = int.Parse(Console.ReadLine());
                Console.WriteLine("Enter another no Y");
                v2 = int.Parse(Console.ReadLine());
                a1 = new ClassA();
                v3 = a1.M1(v1, v2);
                Console.WriteLine("Result of {0}/{1}={2}", v1, v2, v3);
            }
            catch (Exception err)
            {
                Console.WriteLine("Error1 StackTrace:\n " + err.StackTrace);
                Console.WriteLine("Error1 TargetSite:\n " + err.TargetSite.Name);
            }
        }
        public static void NestedTryDemo()
        {
            int x = 0; int y = 0; int z = 0;
            Calculator c1 = null;
            Console.WriteLine("Before Try1");
            try
            {
                Console.WriteLine("Inside Try1");
                try
                {
                    Console.WriteLine("\tInside Nested Try");
                    Console.WriteLine("\tEnter a no");
                    x = int.Parse(Console.ReadLine());
                    Console.WriteLine("\tEnter a no");
                    y = int.Parse(Console.ReadLine());
                    c1 = new Calculator();
                    z = c1.Divide(x, y);
                }
                catch (FormatException err)
                {
                    Console.WriteLine("\tInside NestedCatch " + err.Message);
                    throw err;//re throw
                    //throw new Exception("Test msg");
                }
                finally
                {
                    Console.WriteLine("\tInside Nested  ly");
                }
                Console.WriteLine("Inside outer Try1 After Nested  ly");
                Console.WriteLine("Result " + z);
            }
            catch (DivideByZeroException err)
            {
                Console.WriteLine("Inside outer Catch1 " + err.Message);
            }
            catch (NullReferenceException err)
            {
                Console.WriteLine("Inside outer Catch2 " + err.Message);
            }
            catch (FormatException err)
            {
                Console.WriteLine("Inside outer Catch3 " + err.Message);
            }
            catch (Exception err)
            {
                Console.WriteLine("Inside outer Catch4 " + err.Message);
            }
            finally
            {
                Console.WriteLine("Inside outer  ly1");
            }
            Console.WriteLine("After outer  ly1");
        }
    }
}
